<?xml version="1.0" ?>
<!-- =================================================================================== -->
<!-- |    This document was autogenerated by xacro from bravo_7_example.urdf.xacro     | -->
<!-- |    EDITING THIS FILE BY HAND IS NOT RECOMMENDED                                 | -->
<!-- =================================================================================== -->
<robot name="bravo_7_example">
  <!-- See K&D properties: -->
  <!-- https://blueprint-lab.github.io/Blueprint_Lab_Software/documentation/index.html -->
  <!-- https://en.wikipedia.org/wiki/Denavit%E2%80%93Hartenberg_parameters#:~:text=handed%20coordinate%20system.-,Four%20parameters,-%5Bedit%5D -->
  <link name="world"/>
  <joint name="bravo_joint" type="fixed">
    <origin rpy="0 0 0" xyz="0 0 0"/>
    <parent link="world"/>
    <child link="bravo_base_link"/>
    <origin rpy="0 0 0" xyz="0 0 0"/>
    <dynamics damping="3.0" friction="0.0"/>
  </joint>
  <material name="bravo_black">
    <color rgba="0.3 0.3 0.3 1"/>
  </material>
  <!-- base -->
  <link name="bravo_base_link">
    <visual>
      <geometry>
        <mesh filename="package://bpl_bravo_description_real/meshes/RS2-1019_base.stl"/>
      </geometry>
      <material name="bravo_black"/>
    </visual>
    <collision>
      <geometry>
        <box size="0.0725 0.1112 0.083"/>
      </geometry>
      <origin rpy="0 0 0" xyz="0.03625 00 0.0415"/>
    </collision>
    <collision>
      <geometry>
        <box size="0.050 0.080 0.060"/>
      </geometry>
      <origin rpy="0 0 0" xyz="0.025 -0.04556 0.03"/>
    </collision>
    <collision>
      <geometry>
        <cylinder length="0.083" radius="0.046"/>
      </geometry>
      <origin rpy="0 0 0" xyz="0.0665 0 0.0415"/>
    </collision>
    <inertial>
      <mass value="1.25"/>
      <origin xyz="-0.075 -0.006 -0.003"/>
      <inertia ixx="0.002108" ixy="0.00018199999999999998" ixz="-1.4999999999999999e-05" iyy="0.0025729999999999998" iyz="-2.1e-05" izz="0.003483"/>
    </inertial>
  </link>
  <joint name="bravo_axis_g" type="revolute">
    <parent link="bravo_base_link"/>
    <origin rpy="0 0 3.14159" xyz="0.0665 0 0.08"/>
    <axis xyz="0 0 -1"/>
    <child link="bravo_1019_end_link"/>
    <!-- <safety_controller k_position="100.0" k_velocity="40.0"/> -->
    <limit effort="500" lower="0.0" upper="6.2" velocity="3"/>
    <dynamics damping="3.0" friction="0.0"/>
  </joint>
  <link name="bravo_1019_end_link">
    <visual>
      <geometry>
        <mesh filename="package://bpl_bravo_description_real/meshes/RS2-1019_end.stl"/>
      </geometry>
      <material name="bravo_black"/>
    </visual>
    <!-- Add same mesh as collision to correct bug -->
    <collision>
      <geometry>
        <mesh filename="package://bpl_bravo_description_real/meshes/RS2-1019_end.stl"/>
      </geometry>
      <material name="bravo_black"/>
    </collision>
    <!-- Low mass for unimportant link -->
    <inertial>
      <mass value="0.01"/>
      <inertia ixx="0.000000001" ixy="0.0" ixz="0.0" iyy="0.000000001" iyz="0.0" izz="0.000000001"/>
    </inertial>
  </link>
  <joint name="bravo_f_base_joint" type="fixed">
    <parent link="bravo_1019_end_link"/>
    <origin rpy="0 0 0" xyz="0 0 0"/>
    <child link="bravo_1013_base_link"/>
  </joint>
  <!-- shoulder -->
  <link name="bravo_1013_base_link">
    <visual>
      <geometry>
        <mesh filename="package://bpl_bravo_description_real/meshes/RS2-1013_base.stl"/>
      </geometry>
      <material name="bravo_black"/>
    </visual>
    <collision>
      <geometry>
        <cylinder length="0.030" radius="0.046"/>
      </geometry>
      <origin rpy="0 0 0" xyz="0.0 00 0.015"/>
    </collision>
    <collision>
      <geometry>
        <cylinder length="0.1" radius="0.046"/>
      </geometry>
      <origin rpy="1.5707 0 0 " xyz="0.048 00 0.0642"/>
    </collision>
    <inertial>
      <mass value="1.55"/>
      <inertia ixx="0.011441999999999999" ixy="-0.000484" ixz="0.003405" iyy="0.01298" iyz="-0.0012649999999999998" izz="0.003202"/>
      <origin xyz="0.005 -0.001 0.016"/>
    </inertial>
  </link>
  <joint name="bravo_axis_f" type="revolute">
    <parent link="bravo_1013_base_link"/>
    <origin rpy="0 0 0" xyz="0.046 0 0.0642"/>
    <axis xyz="0 -1 0"/>
    <child link="bravo_1013_joint_link"/>
    <limit effort="500" lower="0.0" upper="3.14" velocity="3"/>
    <dynamics damping="3.0" friction="0.0"/>
  </joint>
  <link name="bravo_1013_joint_link">
    <visual>
      <geometry>
        <mesh filename="package://bpl_bravo_description_real/meshes/RS2-1013_end.stl"/>
      </geometry>
      <material name="bravo_black"/>
    </visual>
    <collision>
      <geometry>
        <cylinder length="0.03" radius="0.046"/>
      </geometry>
      <origin rpy="0 0 0" xyz="0.046 0 -0.03555"/>
    </collision>
    <!-- Low mass for unimportant link -->
    <inertial>
      <mass value="0.01"/>
      <inertia ixx="0.000000001" ixy="0.0" ixz="0.0" iyy="0.000000001" iyz="0.0" izz="0.000000001"/>
    </inertial>
  </link>
  <joint name="bravo_1013_end_joint" type="fixed">
    <parent link="bravo_1013_joint_link"/>
    <origin rpy="3.14159 0 3.14159" xyz="0.046 0 -0.05055"/>
    <child link="bravo_1013_end_link"/>
  </joint>
  <link name="bravo_1013_end_link">
    <!-- Low mass for unimportant link -->
    <inertial>
      <mass value="0.01"/>
      <inertia ixx="0.000000001" ixy="0.0" ixz="0.0" iyy="0.000000001" iyz="0.0" izz="0.000000001"/>
    </inertial>
  </link>
  <joint name="bravo_e_base_joint" type="fixed">
    <parent link="bravo_1013_end_link"/>
    <origin rpy="0 0 0" xyz="0 0 0.182"/>
    <child link="bravo_1026_0_base_link"/>
  </joint>
  <link name="bravo_1026_0_base_link">
    <visual>
      <geometry>
        <mesh filename="package://bpl_bravo_description_real/meshes/RS2-1026_0_base.stl"/>
      </geometry>
      <material name="bravo_black"/>
    </visual>
    <collision>
      <geometry>
        <cylinder length="0.03" radius="0.0408"/>
      </geometry>
      <origin rpy="0 0 0" xyz="0 00 0.015"/>
    </collision>
    <collision>
      <geometry>
        <cylinder length="0.0816" radius="0.0408"/>
      </geometry>
      <origin rpy="1.5707 0 0" xyz="0.0408 00 0.0578"/>
    </collision>
    <inertial>
      <mass value="1.14"/>
      <origin xyz="0.022 -0.029 0.001"/>
      <inertia ixx="0.0032129999999999997" ixy="-0.001548" ixz="-3.1e-05" iyy="0.002327" iyz="6e-06" izz="0.00434"/>
    </inertial>
  </link>
  <joint name="bravo_axis_e" type="revolute">
    <parent link="bravo_1026_0_base_link"/>
    <origin rpy="0 0 0" xyz="0.042 0 0.0578"/>
    <axis xyz="0 -1 0"/>
    <child link="bravo_1026_0_joint_link"/>
    <limit effort="500" lower="0.0" upper="3.14" velocity="3"/>
    <dynamics damping="3.0" friction="0.0"/>
  </joint>
  <!-- forearm link -->
  <link name="bravo_1026_0_joint_link">
    <visual>
      <geometry>
        <mesh filename="package://bpl_bravo_description_real/meshes/RS2-1026_0_end.stl"/>
      </geometry>
      <material name="bravo_black"/>
    </visual>
    <collision>
      <geometry>
        <cylinder length="0.080" radius="0.0408"/>
      </geometry>
      <origin rpy="0 0 0" xyz="0.0408 0 -0.05385"/>
    </collision>
    <inertial>
      <mass value="0.115"/>
      <origin xyz="0.017 -0.026 -0.002"/>
      <inertia ixx="0.000120" ixy="-0.000061" ixz="-0.000001" iyy="0.000062" iyz="0.000000" izz="0.000156"/>
      <mass value="1.14"/>
      <inertia ixx="0.021231999999999997" ixy="0.00033" ixz="-0.003738" iyy="0.022251999999999997" iyz="-0.0012779999999999998" izz="0.002054"/>
    </inertial>
  </link>
  <joint name="bravo_1026_0_end_joint" type="fixed">
    <parent link="bravo_1026_0_joint_link"/>
    <origin rpy="3.14159 0 0" xyz="0.0408 0 -0.09385"/>
    <child link="bravo_1026_0_end_link"/>
  </joint>
  <link name="bravo_1026_0_end_link">
    <!-- Low mass for unimportant link -->
    <inertial>
      <mass value="0.01"/>
      <inertia ixx="0.000000001" ixy="0.0" ixz="0.0" iyy="0.000000001" iyz="0.0" izz="0.000000001"/>
    </inertial>
  </link>
  <joint name="bravo_d_base_joint" type="fixed">
    <parent link="bravo_1026_0_end_link"/>
    <origin rpy="0 0 0" xyz="0 0 0"/>
    <child link="bravo_1026_1_base_link"/>
  </joint>
  <link name="bravo_1026_1_base_link">
    <!-- Low mass for unimportant link -->
    <inertial>
      <mass value="0.01"/>
      <inertia ixx="0.000000001" ixy="0.0" ixz="0.0" iyy="0.000000001" iyz="0.0" izz="0.000000001"/>
    </inertial>
  </link>
  <joint name="bravo_axis_d" type="revolute">
    <parent link="bravo_1026_1_base_link"/>
    <origin rpy="0 0 0" xyz="0 0 0.0005"/>
    <axis xyz="0 0 -1"/>
    <child link="bravo_1026_1_joint_link"/>
    <limit effort="500" lower="0" upper="6.2" velocity="3"/>
    <dynamics damping="3.0" friction="0.0"/>
  </joint>
  <link name="bravo_1026_1_joint_link">
    <visual>
      <geometry>
        <mesh filename="package://bpl_bravo_description_real/meshes/RS2-1026_1_end.stl"/>
      </geometry>
      <material name="bravo_black"/>
      <origin rpy="0 0 3.14159" xyz="0 0 0 "/>
    </visual>
    <collision>
      <geometry>
        <cylinder length="0.0056" radius="0.0408"/>
      </geometry>
      <origin rpy="0 0 3.14159" xyz="0 0 0.0028"/>
    </collision>
    <!-- Low mass for unimportant link -->
    <inertial>
      <mass value="0.01"/>
      <inertia ixx="0.000000001" ixy="0.0" ixz="0.0" iyy="0.000000001" iyz="0.0" izz="0.000000001"/>
    </inertial>
  </link>
  <joint name="bravo_1026_1_end_joint" type="fixed">
    <parent link="bravo_1026_1_joint_link"/>
    <origin rpy="0 0 3.14159" xyz="0 0 0.0056"/>
    <child link="bravo_1026_1_end_link"/>
  </joint>
  <link name="bravo_1026_1_end_link">
    <!-- Low mass for unimportant link -->
    <inertial>
      <mass value="0.01"/>
      <inertia ixx="0.000000001" ixy="0.0" ixz="0.0" iyy="0.000000001" iyz="0.0" izz="0.000000001"/>
    </inertial>
  </link>
  <joint name="bravo_c_base_joint" type="fixed">
    <parent link="bravo_1026_1_end_link"/>
    <origin rpy="0 0 0" xyz="0 0 0.0"/>
    <child link="bravo_1023_0_base_link"/>
  </joint>
  <link name="bravo_1023_0_base_link">
    <visual>
      <geometry>
        <mesh filename="package://bpl_bravo_description_real/meshes/RS2-1023_0_base.stl"/>
      </geometry>
      <material name="bravo_black"/>
    </visual>
    <collision>
      <geometry>
        <cylinder length="0.03" radius="0.0408"/>
      </geometry>
      <origin rpy="0 0 0" xyz="0 00 0.015"/>
    </collision>
    <collision>
      <geometry>
        <cylinder length="0.0816" radius="0.0408"/>
      </geometry>
      <origin rpy="1.5707 0 0" xyz="0.0408 00 0.0578"/>
    </collision>
    <inertial>
      <mass value="1.03"/>
      <origin xyz="0.020 -0.024 0.001"/>
      <inertia ixx="0.00243" ixy="-0.001144" ixz="-3.9999999999999996e-05" iyy="0.002026" iyz="1.1e-05" izz="0.00333"/>
    </inertial>
  </link>
  <joint name="bravo_axis_c" type="revolute">
    <parent link="bravo_1023_0_base_link"/>
    <origin rpy="0 0 0" xyz="0.042 0 0.0578"/>
    <axis xyz="0 -1 0"/>
    <child link="bravo_1023_0_joint_link"/>
    <limit effort="500" lower="0.0" upper="3.2" velocity="3"/>
    <dynamics damping="3.0" friction="0.0"/>
  </joint>
  <!-- wrist_link1 -->
  <link name="bravo_1023_0_joint_link">
    <visual>
      <geometry>
        <mesh filename="package://bpl_bravo_description_real/meshes/RS2-1023_0_end.stl"/>
      </geometry>
      <material name="bravo_black"/>
    </visual>
    <collision>
      <geometry>
        <cylinder length="0.080" radius="0.0408"/>
      </geometry>
      <origin rpy="0 0 0" xyz="0.0408 0 -0.05385"/>
    </collision>
    <inertial>
      <mass value="0.333"/>
      <origin xyz="0.0 0.003 -0.098"/>
      <inertia ixx="0.003709" ixy="-0.000002" ixz="-0.000004" iyy="0.003734" iyz="0.000000" izz="0.000079"/>
    </inertial>
  </link>
  <joint name="bravo_1023_0_end_joint" type="fixed">
    <parent link="bravo_1023_0_joint_link"/>
    <origin rpy="3.14159 0 0" xyz="0.0408 0 -0.09385"/>
    <child link="bravo_1023_0_end_link"/>
  </joint>
  <link name="bravo_1023_0_end_link">
    <!-- Low mass for unimportant link -->
    <inertial>
      <mass value="0.01"/>
      <inertia ixx="0.000000001" ixy="0.0" ixz="0.0" iyy="0.000000001" iyz="0.0" izz="0.000000001"/>
    </inertial>
  </link>
  <joint name="bravo_b_base_joint" type="fixed">
    <parent link="bravo_1023_0_end_link"/>
    <origin rpy="0 0 0" xyz="0 0 0"/>
    <child link="bravo_1023_1_base_link"/>
  </joint>
  <link name="bravo_1023_1_base_link">
    <!-- Low mass for unimportant link -->
    <inertial>
      <mass value="0.01"/>
      <inertia ixx="0.000000001" ixy="0.0" ixz="0.0" iyy="0.000000001" iyz="0.0" izz="0.000000001"/>
    </inertial>
  </link>
  <joint name="bravo_axis_b" type="continuous">
    <parent link="bravo_1023_1_base_link"/>
    <origin rpy="0 0 0" xyz="0 0 0.0005"/>
    <axis xyz="0 0 -1"/>
    <child link="bravo_1023_1_joint_link"/>
    <limit effort="500" lower="0.0" upper="6.2" velocity="3"/>
    <dynamics damping="3.0" friction="0.0"/>
  </joint>
  <link name="bravo_1023_1_joint_link">
    <visual>
      <geometry>
        <mesh filename="package://bpl_bravo_description_real/meshes/RS2-1023_1_end.stl"/>
      </geometry>
      <material name="bravo_black"/>
    </visual>
    <collision>
      <geometry>
        <cylinder length="0.0056" radius="0.0408"/>
      </geometry>
      <origin rpy="0 0 0" xyz="0 0 0.0028"/>
    </collision>
    <!-- Low mass for unimportant link -->
    <inertial>
      <mass value="0.01"/>
      <inertia ixx="0.000000001" ixy="0.0" ixz="0.0" iyy="0.000000001" iyz="0.0" izz="0.000000001"/>
    </inertial>
  </link>
  <joint name="bravo_1023_1_end_joint" type="fixed">
    <parent link="bravo_1023_1_joint_link"/>
    <origin rpy="0 0 0" xyz="0 0 0.0056"/>
    <child link="bravo_1023_1_end_link"/>
  </joint>
  <link name="bravo_1023_1_end_link">
    <!-- Low mass for unimportant link -->
    <inertial>
      <mass value="0.01"/>
      <inertia ixx="0.000000001" ixy="0.0" ixz="0.0" iyy="0.000000001" iyz="0.0" izz="0.000000001"/>
    </inertial>
  </link>
  <joint name="bravo_a_base_joint" type="fixed">
    <parent link="bravo_1023_1_end_link"/>
    <origin rpy="0 0 0" xyz="0 0 0"/>
    <child link="bravo_1028_base_link"/>
  </joint>
  <!-- wrist_link2 -->
  <link name="bravo_1028_base_link">
    <visual>
      <geometry>
        <mesh filename="package://bpl_bravo_description_real/meshes/RS2-1028.stl"/>
      </geometry>
      <material name="bravo_black"/>
    </visual>
    <collision>
      <geometry>
        <cylinder length="0.120" radius="0.0408"/>
      </geometry>
      <origin rpy="0 0 0" xyz="0 0 0.06"/>
    </collision>
    <inertial>
      <origin xyz="0.0 0.003 -0.098"/>
      <mass value="1.04"/>
      <inertia ixx="0.022359" ixy="1e-06" ixz="-1.8999999999999998e-05" iyy="0.022362999999999997" iyz="1.4999999999999999e-05" izz="0.000936"/>
    </inertial>
  </link>
  <joint name="bravo_1028_end_joint" type="fixed">
    <parent link="bravo_1028_base_link"/>
    <origin rpy="-1.5707 -1.5707 0" xyz="0 0 0.120"/>
    <child link="bravo_1028_end_link"/>
  </joint>
  <link name="bravo_1028_end_link">
    <!-- Low mass for unimportant link -->
    <inertial>
      <mass value="0.01"/>
      <inertia ixx="0.000000001" ixy="0.0" ixz="0.0" iyy="0.000000001" iyz="0.0" izz="0.000000001"/>
    </inertial>
  </link>
  <joint name="bravo_jaws_joint" type="fixed">
    <origin rpy="0 0 0" xyz=" 0 0 0.0"/>
    <parent link="bravo_1028_end_link"/>
    <child link="bravo_jaws_base_link"/>
  </joint>
  <link name="bravo_jaws_base_link">
    <!--        <visual>-->
    <!--            <geometry>-->
    <!--                <mesh filename="package://bpl_bravo_description_real/meshes/end_effectors/RS2-257.stl"/>-->
    <!--            </geometry>-->
    <!--            <material name="bravo_jaws_black"/>-->
    <!--            </visual>-->
    <!-- Low mass for unimportant link -->
    <inertial>
      <mass value="0.01"/>
      <inertia ixx="0.000000001" ixy="0.0" ixz="0.0" iyy="0.000000001" iyz="0.0" izz="0.000000001"/>
    </inertial>
  </link>
  <link name="bravo_push_rod">
    <!-- Low mass for unimportant link -->
    <inertial>
      <mass value="0.1"/>
      <inertia ixx="0.0001" ixy="0.0" ixz="0.0" iyy="0.0001" iyz="0.0" izz="0.0001"/>
    </inertial>
  </link>
  <joint name="bravo_axis_a" type="prismatic">
    <origin rpy="0 0 0" xyz="0 0 0.009"/>
    <parent link="bravo_jaws_base_link"/>
    <child link="bravo_push_rod"/>
    <axis xyz="0 0 1"/>
    <limit effort="500" lower="0" upper="0.035" velocity="3"/>
    <dynamics damping="3.0" friction="0.0"/>
  </joint>
  <!-- Upper arm -->
  <link name="bravo_1030_base_link">
    <visual>
      <geometry>
        <mesh filename="package://bpl_bravo_description_real/meshes/RS2-1030.stl"/>
      </geometry>
      <material name="bravo_black"/>
    </visual>
    <collision>
      <geometry>
        <cylinder length="0.03033333" radius="0.046"/>
      </geometry>
      <origin rpy="0 0 0" xyz="0 0 0.01516666"/>
    </collision>
    <collision>
      <geometry>
        <cylinder length="0.03033333" radius="0.045"/>
      </geometry>
      <origin rpy="0 0 0" xyz="0 0 0.0455"/>
    </collision>
    <collision>
      <geometry>
        <cylinder length="0.03033333" radius="0.044"/>
      </geometry>
      <origin rpy="0 0 0" xyz="0 0 0.075833333"/>
    </collision>
    <collision>
      <geometry>
        <cylinder length="0.03033333" radius="0.043"/>
      </geometry>
      <origin rpy="0 0 0" xyz="0 0 0.1061666666"/>
    </collision>
    <collision>
      <geometry>
        <cylinder length="0.03033333" radius="0.042"/>
      </geometry>
      <origin rpy="0 0 0" xyz="0 0 0.1365"/>
    </collision>
    <collision>
      <geometry>
        <cylinder length="0.03033333" radius="0.041"/>
      </geometry>
      <origin rpy="0 0 0" xyz="0 0 0.1668333"/>
    </collision>
    <inertial>
      <origin xyz="0.073 0.0 0.0"/>
      <mass value="1.98"/>
      <inertia ixx="0.00396" ixy="0.0042" ixz="0.003204" iyy="0.069099" iyz="-2.4e-05" izz="0.07045"/>
    </inertial>
  </link>
  <joint name="bravo_1030_base_joint" type="fixed">
    <parent link="bravo_1013_end_link"/>
    <child link="bravo_1030_base_link"/>
    <origin rpy="0 0 0" xyz="0 0 0"/>
  </joint>
  <material name="bravo_finger_jaws_black">
    <color rgba="0.3 0.3 0.3 1"/>
  </material>
  <joint name="bravo_finger_jaws_joint" type="fixed">
    <origin rpy="-0.6 0 0" xyz="0 0 0"/>
    <parent link="bravo_jaws_base_link"/>
    <child link="bravo_finger_jaws_base_link"/>
    <origin rpy="0 0 0" xyz="0 0 0"/>
  </joint>
  <link name="bravo_finger_jaws_base_link">
    <visual>
      <geometry>
        <mesh filename="package://rsa_bravo_gazebo/meshes/end_effectors/RS2-257.stl"/>
      </geometry>
      <material name="bravo_finger_jaws_black"/>
    </visual>
    <collision>
      <geometry>
        <cylinder length="0.02" radius="0.05"/>
      </geometry>
      <origin rpy="0 1.5707 0" xyz="0.01 0 0.00"/>
    </collision>
    <!-- Low mass for unimportant link -->
    <inertial>
      <mass value="0.01"/>
      <inertia ixx="0.0001" ixy="0.0" ixz="0.0" iyy="0.0001" iyz="0.0" izz="0.0001"/>
    </inertial>
  </link>
  <!-- virtual link with different orientation for planning -->
  <link name="ee_link"/>
  <joint name="ee_link_joint" type="fixed">
    <origin rpy="0 1.5708 0" xyz="0 0 0"/>
    <parent link="bravo_finger_jaws_base_link"/>
    <child link="ee_link"/>
  </joint>
  <link name="bravo_finger_jaws_rs2_300_link">
    <visual>
      <geometry>
        <mesh filename="package://rsa_bravo_gazebo/meshes/end_effectors/RS2-300.stl"/>
      </geometry>
      <material name="bravo_finger_jaws_black"/>
    </visual>
    <collision>
      <geometry>
        <mesh filename="package://rsa_bravo_gazebo/meshes/end_effectors/RS2-300.stl"/>
      </geometry>
      <!-- <geometry>
                    <box size="0.14 0.04 0.045"/>
                </geometry>
                <origin xyz="0.07 0.025 0.00" rpy="0 0 0.35"/> -->
    </collision>
    <!-- copied from link 6 of the datasheet, which includes BOTH fingers, so I cut the mass in half. The inertia tensor probably might be good to within an order of magnitude. -->
    <inertial>
      <mass value="0.24"/>
      <origin xyz="0.05 0.0 0"/>
      <inertia ixx="0.000244" ixy="-1.2e-05" ixz="0.0" iyy="0.00113" iyz="1e-06" izz="0.001178"/>
    </inertial>
  </link>
  <joint name="bravo_finger_jaws_rs2_300_joint" type="revolute">
    <origin rpy="0 0 0" xyz="0.0097 -0.033 0"/>
    <parent link="bravo_finger_jaws_base_link"/>
    <child link="bravo_finger_jaws_rs2_300_link"/>
    <axis xyz="0 0 -1"/>
    <limit effort="400" lower="0" upper="1.0" velocity="3"/>
    <mimic joint="bravo_axis_a" multiplier="18" offset="0"/>
  </joint>
  <link name="bravo_finger_jaws_rs2_301_link">
    <visual>
      <geometry>
        <mesh filename="package://rsa_bravo_gazebo/meshes/end_effectors/RS2-301.stl"/>
      </geometry>
      <material name="bravo_finger_jaws_black"/>
    </visual>
    <collision>
      <geometry>
        <mesh filename="package://rsa_bravo_gazebo/meshes/end_effectors/RS2-301.stl"/>
      </geometry>
      <!-- <geometry>
                    <box size="0.14 0.04 0.045"/>
                </geometry>
                <origin xyz="0.07 -0.025 0.00" rpy="0 0 -0.35"/> -->
    </collision>
    <!-- copied from link 6 of the datasheet, which includes BOTH fingers, so I cut the mass in half. The inertia tensor probably might be good to within an order of magnitude. -->
    <inertial>
      <mass value="0.24"/>
      <origin xyz="0.05 0.0 0"/>
      <inertia ixx="0.000244" ixy="-1.2e-05" ixz="0.0" iyy="0.00113" iyz="1e-06" izz="0.001178"/>
    </inertial>
  </link>
  <joint name="bravo_finger_jaws_rs2_301_joint" type="revolute">
    <origin rpy="0 0 0" xyz="0.0097 0.033 0"/>
    <parent link="bravo_finger_jaws_base_link"/>
    <child link="bravo_finger_jaws_rs2_301_link"/>
    <axis xyz="0 0 1"/>
    <limit effort="400" lower="0" upper="1.0" velocity="3"/>
    <mimic joint="bravo_finger_jaws_rs2_300_joint" multiplier="1" offset="0"/>
  </joint>
  <gazebo>
    <plugin filename="libroboticsgroup_upatras_gazebo_mimic_joint_plugin.so" name="bravo_finger_jaws_rs2_300_jointmimic_joint_plugin">
      <joint>bravo_axis_a</joint>
      <mimicJoint>bravo_finger_jaws_rs2_300_joint</mimicJoint>
      <multiplier>18.0</multiplier>
      <offset>0</offset>
      <sensitiveness>0.0</sensitiveness>
      <!-- if absolute difference between setpoint and process value is below this threshold, do nothing; 0.0 = disable [rad] -->
      <maxEffort>100.0</maxEffort>
      <robotNamespace>bravo</robotNamespace>
    </plugin>
  </gazebo>
  <gazebo>
    <plugin filename="libroboticsgroup_upatras_gazebo_mimic_joint_plugin.so" name="bravo_finger_jaws_rs2_301_jointmimic_joint_plugin">
      <joint>bravo_axis_a</joint>
      <mimicJoint>bravo_finger_jaws_rs2_301_joint</mimicJoint>
      <multiplier>18.0</multiplier>
      <offset>0</offset>
      <sensitiveness>0.0</sensitiveness>
      <!-- if absolute difference between setpoint and process value is below this threshold, do nothing; 0.0 = disable [rad] -->
      <maxEffort>100.0</maxEffort>
      <robotNamespace>bravo</robotNamespace>
    </plugin>
  </gazebo>
  <!-- axis_g -->
  <gazebo reference="bravo_axis_g">
    <implicitSpringDamper>1</implicitSpringDamper>
  </gazebo>
  <!-- axis_f -->
  <gazebo reference="bravo_axis_f">
    <implicitSpringDamper>1</implicitSpringDamper>
  </gazebo>
  <!-- axis_e -->
  <gazebo reference="bravo_axis_e">
    <implicitSpringDamper>1</implicitSpringDamper>
  </gazebo>
  <!-- axis_d -->
  <gazebo reference="bravo_axis_d">
    <implicitSpringDamper>1</implicitSpringDamper>
  </gazebo>
  <!-- axis_c -->
  <gazebo reference="bravo_axis_c">
    <implicitSpringDamper>1</implicitSpringDamper>
  </gazebo>
  <!-- axis_b -->
  <gazebo reference="bravo_axis_b">
    <implicitSpringDamper>1</implicitSpringDamper>
  </gazebo>
  <!-- axis_a -->
  <gazebo reference="bravo_axis_a">
    <implicitSpringDamper>1</implicitSpringDamper>
  </gazebo>
  <!-- Links (added for all links with collision geometry -->
  <gazebo reference="bravo_base_link">
    <mu1>0.2</mu1>
    <mu2>0.2</mu2>
    <turnGravityOff>true</turnGravityOff>
    <!-- gravity is turned off in all these links because moveit_servo + roscontrol don't have gravity compensation built in. -->
  </gazebo>
  <gazebo reference="bravo_1019_end_link">
    <mu1>0.2</mu1>
    <mu2>0.2</mu2>
    <turnGravityOff>true</turnGravityOff>
  </gazebo>
  <gazebo reference="bravo_1013_base_link">
    <mu1>0.2</mu1>
    <mu2>0.2</mu2>
    <turnGravityOff>true</turnGravityOff>
  </gazebo>
  <gazebo reference="bravo_1013_end_link">
    <mu1>0.2</mu1>
    <mu2>0.2</mu2>
    <turnGravityOff>true</turnGravityOff>
  </gazebo>
  <!-- 1013_joint_link -->
  <gazebo reference="bravo_1013_joint_link">
    <mu1>0.2</mu1>
    <mu2>0.2</mu2>
    <turnGravityOff>true</turnGravityOff>
  </gazebo>
  <!-- 1026_0_base_link -->
  <gazebo reference="bravo_1026_0_base_link">
    <mu1>0.2</mu1>
    <mu2>0.2</mu2>
    <turnGravityOff>true</turnGravityOff>
  </gazebo>
  <!-- 1026_0_joint_link -->
  <gazebo reference="bravo_1026_0_joint_link">
    <mu1>0.2</mu1>
    <mu2>0.2</mu2>
    <turnGravityOff>true</turnGravityOff>
  </gazebo>
  <gazebo reference="bravo_1026_0_end_link">
    <mu1>0.2</mu1>
    <mu2>0.2</mu2>
    <turnGravityOff>true</turnGravityOff>
  </gazebo>
  <gazebo reference="bravo_1026_1_base_link">
    <mu1>0.2</mu1>
    <mu2>0.2</mu2>
    <turnGravityOff>true</turnGravityOff>
  </gazebo>
  <!-- 1026_1_joint_link -->
  <gazebo reference="bravo_1026_1_joint_link">
    <mu1>0.2</mu1>
    <mu2>0.2</mu2>
    <turnGravityOff>true</turnGravityOff>
  </gazebo>
  <gazebo reference="bravo_1026_1_end_link">
    <mu1>0.2</mu1>
    <mu2>0.2</mu2>
    <turnGravityOff>true</turnGravityOff>
  </gazebo>
  <!-- 1023_0_base_link -->
  <gazebo reference="bravo_1023_0_base_link">
    <mu1>0.2</mu1>
    <mu2>0.2</mu2>
    <turnGravityOff>true</turnGravityOff>
  </gazebo>
  <!-- 1023_0_joint_link -->
  <gazebo reference="bravo_1023_0_joint_link">
    <mu1>0.2</mu1>
    <mu2>0.2</mu2>
    <turnGravityOff>true</turnGravityOff>
  </gazebo>
  <gazebo reference="bravo_1023_0_end_link">
    <mu1>0.2</mu1>
    <mu2>0.2</mu2>
    <turnGravityOff>true</turnGravityOff>
  </gazebo>
  <gazebo reference="bravo_1023_1_base_link">
    <mu1>0.2</mu1>
    <mu2>0.2</mu2>
    <turnGravityOff>true</turnGravityOff>
  </gazebo>
  <!-- 1023_1_joint_link -->
  <gazebo reference="bravo_1023_1_joint_link">
    <mu1>0.2</mu1>
    <mu2>0.2</mu2>
    <turnGravityOff>true</turnGravityOff>
  </gazebo>
  <gazebo reference="bravo_1023_1_end_link">
    <mu1>0.2</mu1>
    <mu2>0.2</mu2>
    <turnGravityOff>true</turnGravityOff>
  </gazebo>
  <!-- 1028_base_link -->
  <gazebo reference="bravo_1028_base_link">
    <mu1>0.2</mu1>
    <mu2>0.2</mu2>
    <turnGravityOff>true</turnGravityOff>
  </gazebo>
  <gazebo reference="bravo_1028_end_link">
    <mu1>0.2</mu1>
    <mu2>0.2</mu2>
    <turnGravityOff>true</turnGravityOff>
  </gazebo>
  <gazebo reference="bravo_jaws_base_link">
    <mu1>0.2</mu1>
    <mu2>0.2</mu2>
    <turnGravityOff>true</turnGravityOff>
  </gazebo>
  <!-- 1030_base_link -->
  <gazebo reference="bravo_1030_base_link">
    <mu1>0.2</mu1>
    <mu2>0.2</mu2>
    <turnGravityOff>true</turnGravityOff>
  </gazebo>
  <gazebo reference="bravo_finger_jaws_base_link">
    <mu1>0.2</mu1>
    <mu2>0.2</mu2>
    <turnGravityOff>true</turnGravityOff>
  </gazebo>
  <gazebo reference="bravo_push_rod">
    <turnGravityOff>true</turnGravityOff>
  </gazebo>
  <!-- Finger 1 -->
  <gazebo reference="bravo_finger_jaws_rs2_300_link">
    <material>Gazebo/Grey</material>
    <implicitSpringDamper>1</implicitSpringDamper>
    <mu1>5.0</mu1>
    <mu2>5.0</mu2>
    <kp>1e6</kp>
    <kd>1e2</kd>
    <minDepth>0.0</minDepth>
    <maxVel>0.0</maxVel>
    <torsional>
      <ode>
        <coefficient>1000</coefficient>
        <slip>0</slip>
      </ode>
    </torsional>
    <physics>
      <max_contacts>20</max_contacts>
      <ode>
        <limit>
          <cfm>0</cfm>
          <erp>0.2</erp>
        </limit>
        <implicit_spring_damper>1</implicit_spring_damper>
      </ode>
    </physics>
    <turnGravityOff>true</turnGravityOff>
  </gazebo>
  <!-- Finger 2 -->
  <gazebo reference="bravo_finger_jaws_rs2_301_link">
    <material>Gazebo/Grey</material>
    <implicitSpringDamper>1</implicitSpringDamper>
    <mu1>5.0</mu1>
    <mu2>5.0</mu2>
    <kp>1e6</kp>
    <kd>1e2</kd>
    <minDepth>0.0</minDepth>
    <maxVel>0.0</maxVel>
    <torsional>
      <ode>
        <coefficient>1000</coefficient>
        <slip>0</slip>
      </ode>
    </torsional>
    <physics>
      <max_contacts>20</max_contacts>
      <ode>
        <limit>
          <cfm>0</cfm>
          <erp>0.2</erp>
        </limit>
        <implicit_spring_damper>1</implicit_spring_damper>
      </ode>
    </physics>
    <turnGravityOff>true</turnGravityOff>
  </gazebo>
  <!-- Joint Transmissions -->
  <transmission name="trans_bravo_axis_g">
    <type>transmission_interface/SimpleTransmission</type>
    <joint name="bravo_axis_g">
      <hardwareInterface>hardware_interface/EffortJointInterface</hardwareInterface>
    </joint>
    <actuator name="bravo_axis_g_motor">
      <hardwareInterface>hardware_interface/EffortJointInterface</hardwareInterface>
      <mechanicalReduction>1</mechanicalReduction>
    </actuator>
  </transmission>
  <transmission name="trans_bravo_axis_f">
    <type>transmission_interface/SimpleTransmission</type>
    <joint name="bravo_axis_f">
      <hardwareInterface>hardware_interface/EffortJointInterface</hardwareInterface>
    </joint>
    <actuator name="bravo_axis_f_motor">
      <hardwareInterface>hardware_interface/EffortJointInterface</hardwareInterface>
      <mechanicalReduction>1</mechanicalReduction>
    </actuator>
  </transmission>
  <transmission name="trans_bravo_axis_e">
    <type>transmission_interface/SimpleTransmission</type>
    <joint name="bravo_axis_e">
      <hardwareInterface>hardware_interface/EffortJointInterface</hardwareInterface>
    </joint>
    <actuator name="bravo_axis_e_motor">
      <hardwareInterface>hardware_interface/EffortJointInterface</hardwareInterface>
      <mechanicalReduction>1</mechanicalReduction>
    </actuator>
  </transmission>
  <transmission name="trans_bravo_axis_d">
    <type>transmission_interface/SimpleTransmission</type>
    <joint name="bravo_axis_d">
      <hardwareInterface>hardware_interface/EffortJointInterface</hardwareInterface>
    </joint>
    <actuator name="bravo_axis_d_motor">
      <hardwareInterface>hardware_interface/EffortJointInterface</hardwareInterface>
      <mechanicalReduction>1</mechanicalReduction>
    </actuator>
  </transmission>
  <transmission name="trans_bravo_axis_c">
    <type>transmission_interface/SimpleTransmission</type>
    <joint name="bravo_axis_c">
      <hardwareInterface>hardware_interface/EffortJointInterface</hardwareInterface>
    </joint>
    <actuator name="bravo_axis_c_motor">
      <hardwareInterface>hardware_interface/EffortJointInterface</hardwareInterface>
      <mechanicalReduction>1</mechanicalReduction>
    </actuator>
  </transmission>
  <transmission name="trans_bravo_axis_b">
    <type>transmission_interface/SimpleTransmission</type>
    <joint name="bravo_axis_b">
      <hardwareInterface>hardware_interface/EffortJointInterface</hardwareInterface>
    </joint>
    <actuator name="bravo_axis_b_motor">
      <hardwareInterface>hardware_interface/EffortJointInterface</hardwareInterface>
      <mechanicalReduction>1</mechanicalReduction>
    </actuator>
  </transmission>
  <transmission name="trans_bravo_axis_a">
    <type>transmission_interface/SimpleTransmission</type>
    <joint name="bravo_axis_a">
      <hardwareInterface>hardware_interface/EffortJointInterface</hardwareInterface>
    </joint>
    <actuator name="bravo_axis_a_motor">
      <hardwareInterface>hardware_interface/EffortJointInterface</hardwareInterface>
      <mechanicalReduction>1</mechanicalReduction>
    </actuator>
  </transmission>
  <gazebo>
    <plugin filename="libgazebo_ros_control.so" name="gazebo_ros_control">
      <robotNamespace>bravo</robotNamespace>
      <legacyModeNS>True</legacyModeNS>
    </plugin>
  </gazebo>
  <!-- A box to emulate the depth camera -->
  <link name="depth_cam_link">
    <pose>0 0 0 0 0 0</pose>
    <visual>
      <origin rpy="0 0 0" xyz="0 0 0"/>
      <geometry>
        <box size="0.07 0.14 0.070"/>
      </geometry>
      <material name="Orange">
        <color rgba="0.84 0.246 0.035 1.0"/>
      </material>
    </visual>
    <collision>
      <origin rpy="0 0 0" xyz="0 0 0"/>
      <geometry>
        <box size="0.07 0.14 0.070"/>
      </geometry>
    </collision>
  </link>
  <!--
    The depth camera is mounted parallel to the jaws on the wrist, but is measured
    from a frame coincident with bravo_1028_base_link. So we add a virtual link
    to account for the jaw_yaw_offset roll calibration, with the same origin but
    a slight roll.
    -->
  <link name="depth_cam_measurement_link"/>
  <joint name="jaw_offset_frame" type="fixed">
    <parent link="bravo_1028_base_link"/>
    <child link="depth_cam_measurement_link"/>
    <origin rpy="0 0 -0.6" xyz="0 0 0"/>
  </joint>
  <joint name="depth_cam_measurement" type="fixed">
    <parent link="depth_cam_measurement_link"/>
    <child link="depth_cam_link"/>
    <origin rpy="1.5708 -1.5708 0" xyz="-0.006 -0.078 0.040"/>
  </joint>
</robot>

